Workbook

Sheet base de datos
A1: Equipo | B1: id | C1: frecuencia | D1: Actividad | E1: Prioridad | F1: Duración | G1: Area | H1: Linea | I1: Resposable | J1: tipo de operador | K1: Columna1 | L1: Columna1 | M1: Linea
A2: Aplicador de Barniz Liquido | B2: 1 | C2: 1 día | D2: Limpieza de aplicador de barniz | E2: Alta | F2: 00 h 05 m | G2: lineas Automaticas | H2: Soudronic | I2: Alexander Rabanales | J2: Operador | K2: =Tabla14[[#This Row],[id]]&Tabla14[[#This Row],[Resposable]] -> 1Alexander Rabanales | L2: =Tabla14[[#This Row],[id]]&Tabla14[[#This Row],[Resposable]] -> 1Alexander Rabanales | M2: Soudronic
A3: Aplicador de Barniz polvo | B3: 6 | C3: 1 día | D3: Limpieza de brazo aplicador de polvo | E3: Alta | F3: 00 h 02 m | G3: lineas Automaticas | H3: Soudronic | I3: Alexander Rabanales | J3: Operador | K3: =Tabla14[[#This Row],[id]]&Tabla14[[#This Row],[Resposable]] -> 6Alexander Rabanales | L3: =Tabla14[[#This Row],[id]]&Tabla14[[#This Row],[Resposable]] -> 6Alexander Rabanales | M3: Soudronic
A4: Soldadora | B4: 49 | C4: 1 día | D4: Comprobar y limpiar la ranura del alambre en los cabezales | E4: Alta | F4: 00 h 02 m | G4: lineas Automaticas | H4: Soudronic | I4: Alexander Rabanales | J4: Operador | K4: =Tabla14[[#This Row],[id]]&Tabla14[[#This Row],[Resposable]] -> 49Alexander Rabanales | L4: =Tabla14[[#This Row],[id]]&Tabla14[[#This Row],[Resposable]] -> 49Alexander Rabanales | M4: Soudronic
A5: Soldadora | B5: 49 | C5: 1 día | D5: Limpiar o girar los discos limpiadores de alambre | E5: Alta | F5: 00 h 02 m | G5: lineas Automaticas | H5: Soudronic | I5: Alexander Rabanales | J5: Operador | K5: =Tabla14[[#This Row],[id]]&Tabla14[[#This Row],[Resposable]] -> 49Alexander Rabanales | L5: =Tabla14[[#This Row],[id]]&Tabla14[[#This Row],[Resposable]] -> 49Alexander Rabanales | M5: Soudronic
A6: Soldadora | B6: 49 | C6: 1 día | D6: Limpieza de rodillos del alimentador y formadora de cuerpos | E6: Alta | F6: 00 h 02 m | G6: lineas Automaticas | H6: Soudronic | I6: Alexander Rabanales | J6: Operador | K6: =Tabla14[[#This Row],[id]]&Tabla14[[#This Row],[Resposable]] -> 49Alexander Rabanales | L6: =Tabla14[[#This Row],[id]]&Tabla14[[#This Row],[Resposable]] -> 49Alexander Rabanales | M6: Soudronic
A7: Tijeras automaticas 202 | B7: 123 | C7: 1 día | D7: Limpieza de superficie | E7: Alta | F7: 00 h 02 m | G7: lineas Automaticas | H7: Tijeras | I7: Andres Rabanales | J7: Operador | K7: =Tabla14[[#This Row],[id]]&Tabla14[[#This Row],[Resposable]] -> 123Andres Rabanales | L7: =Tabla14[[#This Row],[id]]&Tabla14[[#This Row],[Resposable]] -> 123Andres Rabanales | M7: Tijeras
A8: Tijeras automaticas 202 | B8: 123 | C8: 1 semana | D8: Lubricacion y limpieza de sistema de barras | E8: Alta | F8: 00 h 15 m | G8: lineas Automaticas | H8: Tijeras | I8: Andres Rabanales | J8: Operador | K8: =Tabla14[[#This Row],[id]]&Tabla14[[#This Row],[Resposable]] -> 123Andres Rabanales | L8: =Tabla14[[#This Row],[id]]&Tabla14[[#This Row],[Resposable]] -> 123Andres Rabanales | M8: Tijeras
A9: Tijeras automaticas 202 | B9: 123 | C9: 1 día | D9: Verificación de cojines, rodillos, tensores y sprocket | E9: Alta | F9: 00 h 03 m | G9: lineas Automaticas | H9: Tijeras | I9: Andres Rabanales | J9: Operador | K9: =Tabla14[[#This Row],[id]]&Tabla14[[#This Row],[Resposable]] -> 123Andres Rabanales | L9: =Tabla14[[#This Row],[id]]&Tabla14[[#This Row],[Resposable]] -> 123Andres Rabanales | M9: Tijeras
A10: Pestañadora envase industrial | B10: 204 | C10: 1 mes | D10: Comprobación de sistema de lubricación | E10: Alta | F10: 00 h 30 m | G10: lineas Automaticas | H10: Envase Pequeño | I10: Anthony Campos | J10: Mecánico | K10: =Tabla14[[#This Row],[id]]&Tabla14[[#This Row],[Resposable]] -> 204Anthony Campos | L10: =Tabla14[[#This Row],[id]]&Tabla14[[#This Row],[Resposable]] -> 204Anthony Campos | M10: Envase Pequeño
A11: Pestañadora envase industrial | B11: 204 | C11: 1 semana | D11: Limpieza de cadena de rodillos | E11: Alta | F11: 00 h 20 m | G11: lineas Automaticas | H11: Envase Pequeño | I11: Anthony Campos | J11: Mecánico | K11: =Tabla14[[#This Row],[id]]&Tabla14[[#This Row],[Resposable]] -> 204Anthony Campos | L11: =Tabla14[[#This Row],[id]]&Tabla14[[#This Row],[Resposable]] -> 204Anthony Campos | M11: Envase Pequeño
A12: Pestañadora envase industrial | B12: 204 | C12: 1 día | D12: Limpieza de platos y shocks de cabezales | E12: Alta | F12: 00 h 05 m | G12: lineas Automaticas | H12: Envase Pequeño | I12: Anthony Campos | J12: Operador | K12: =Tabla14[[#This Row],[id]]&Tabla14[[#This Row],[Resposable]] -> 204Anthony Campos | L12: =Tabla14[[#This Row],[id]]&Tabla14[[#This Row],[Resposable]] -> 204Anthony Campos | M12: Envase Pequeño
A13: Pestañadora envase industrial | B13: 204 | C13: 1 año | D13: Limpieza de sistema de lubricación | E13: Alta | F13: 03 h 00 m | G13: lineas Automaticas | H13: Envase Pequeño | I13: Anthony Campos | J13: Mecánico | K13: =Tabla14[[#This Row],[id]]&Tabla14[[#This Row],[Resposable]] -> 204Anthony Campos | L13: =Tabla14[[#This Row],[id]]&Tabla14[[#This Row],[Resposable]] -> 204Anthony Campos | M13: Envase Pequeño
... A1213: Volteador | B1213: 156 | C1213: 1 semana | D1213: Verificación de cojines, rodillos, tensores y sprocket | E1213: Alta | F1213: 00 h 05 m | G1213: prensas automaticas | H1213: Bibra | I1213: Willy Chic | J1213: Mecánico | K1213: =Tabla14[[#This Row],[id]]&Tabla14[[#This Row],[Resposable]] -> 156Willy Chic | L1213: =Tabla14[[#This Row],[id]]&Tabla14[[#This Row],[Resposable]] -> 156Willy Chic | M1213: Bibra

Sheet OT
A1: id | B1: numero_ot | C1: aux | D1: equipo_id | E1: tipo_mantenimiento | F1: descripcion | G1: tecnico | H1: observaciones | I1: fecha_creacion | J1: padre | K1: numero_ot
A2: 1 | B2: 1 | C2: =D2&G2 -> 1Alexander Rabanales | D2: 1 | E2: Preventivo | F2: Alta | G2: Alexander Rabanales | H2: Operador | I2: 46028.649 | J2: =VLOOKUP(C2,'base de datos'!L2:M1213,2,FALSE) -> Soudronic | K2: 1
A3: 2 | B3: 2 | C3: =D3&G3 -> 6Alexander Rabanales | D3: 6 | E3: Preventivo | F3: Alta | G3: Alexander Rabanales | H3: Operador | I3: 46029.649 | J3: =VLOOKUP(C3,'base de datos'!L3:M1214,2,FALSE) -> Soudronic | K3: 2
A4: 3 | B4: 3 | C4: =D4&G4 -> 49Alexander Rabanales | D4: 49 | E4: Preventivo | F4: Alta | G4: Alexander Rabanales | H4: Operador | I4: 46030.649 | J4: =VLOOKUP(C4,'base de datos'!L4:M1215,2,FALSE) -> Soudronic | K4: 3
A5: 4 | B5: 4 | C5: =D5&G5 -> 123Andres Rabanales | D5: 123 | E5: Preventivo | F5: Alta | G5: Andres Rabanales | H5: Operador | I5: 46031.649 | J5: =VLOOKUP(C5,'base de datos'!L5:M1216,2,FALSE) -> Tijeras | K5: 4
A6: 5 | B6: 5 | C6: =D6&G6 -> 4Anthony Campos | D6: 4 | E6: Preventivo | F6: Alta | G6: Anthony Campos | H6: Mecánico | I6: 46032.649 | J6: =VLOOKUP(C6,'base de datos'!L6:M1217,2,FALSE) -> Ishin | K6: 5
A7: 6 | B7: 6 | C7: =D7&G7 -> 19Anthony Campos | D7: 19 | E7: Preventivo | F7: Alta | G7: Anthony Campos | H7: Mecánico | I7: 46033.649 | J7: =VLOOKUP(C7,'base de datos'!L7:M1218,2,FALSE) -> Ishin | K7: 6
A8: 7 | B8: 7 | C8: =D8&G8 -> 46Anthony Campos | D8: 46 | E8: Preventivo | F8: Alta | G8: Anthony Campos | H8: Mecánico | I8: 46034.649 | J8: =VLOOKUP(C8,'base de datos'!L8:M1219,2,FALSE) -> Golden Smart 220 | K8: 7
A9: 8 | B9: 8 | C9: =D9&G9 -> 47Anthony Campos | D9: 47 | E9: Preventivo | F9: Alta | G9: Anthony Campos | H9: Mecánico | I9: 46035.649 | J9: =VLOOKUP(C9,'base de datos'!L9:M1220,2,FALSE) -> Ishin | K9: 8
A10: 9 | B10: 9 | C10: =D10&G10 -> 52Anthony Campos | D10: 52 | E10: Preventivo | F10: Alta | G10: Anthony Campos | H10: Mecánico | I10: 46036.649 | J10: =VLOOKUP(C10,'base de datos'!L10:M1221,2,FALSE) -> Ishin | K10: 9
A11: 10 | B11: 10 | C11: =D11&G11 -> 79Anthony Campos | D11: 79 | E11: Preventivo | F11: Alta | G11: Anthony Campos | H11: Mecánico | I11: 46037.649 | J11: =VLOOKUP(C11,'base de datos'!L11:M1222,2,FALSE) -> Ishin | K11: 10
A12: 11 | B12: 11 | C12: =D12&G12 -> 106Anthony Campos | D12: 106 | E12: Preventivo | F12: Alta | G12: Anthony Campos | H12: Mecánico | I12: 46038.649 | J12: =VLOOKUP(C12,'base de datos'!L12:M1223,2,FALSE) -> Ishin | K12: 11
A13: 12 | B13: 12 | C13: =D13&G13 -> 110Anthony Campos | D13: 110 | E13: Preventivo | F13: Alta | G13: Anthony Campos | H13: Mecánico | I13: 46039.649 | J13: =VLOOKUP(C13,'base de datos'!L13:M1224,2,FALSE) -> Ishin | K13: 12
... A17: 16 | B17: 16 | C17: =D17&G17 -> 203Anthony Campos | D17: 203 | E17: Preventivo | F17: Alta | G17: Anthony Campos | H17: Mecánico | I17: 46043.649 | J17: =VLOOKUP(C17,'base de datos'!L17:M1228,2,FALSE) -> Envase Pequeño | K17: 16
A18: 17 | B18: 17 | C18: =D18&G18 -> 204Anthony Campos | D18: 204 | E18: Preventivo | F18: Alta | G18: Anthony Campos | H18: Mecánico | I18: 46044.649 | J18: Envase Pequeño | K18: 17
A19: 18 | B19: 18 | C19: =D19&G19 -> 205Anthony Campos | D19: 205 | E19: Preventivo | F19: Alta | G19: Anthony Campos | H19: Mecánico | I19: 46045.649 | J19: =VLOOKUP(C19,'base de datos'!L19:M1230,2,FALSE) -> Envase Rectangular | K19: 18
A20: 19 | B20: 19 | C20: =D20&G20 -> 207Anthony Campos | D20: 207 | E20: Preventivo | F20: Alta | G20: Anthony Campos | H20: Mecánico | I20: 46046.649 | J20: =VLOOKUP(C20,'base de datos'!L20:M1231,2,FALSE) -> Envase Rectangular | K20: 19
A21: 20 | B21: 20 | C21: =D21&G21 -> 208Anthony Campos | D21: 208 | E21: Preventivo | F21: Alta | G21: Anthony Campos | H21: Mecánico | I21: 46047.649 | J21: =VLOOKUP(C21,'base de datos'!L21:M1232,2,FALSE) -> Envase Rectangular | K21: 20
A22: 21 | B22: 21 | C22: =D22&G22 -> 2Bezalel Mendoza | D22: 2 | E22: Preventivo | F22: Alta | G22: Bezalel Mendoza | H22: Electricista | I22: 46048.649 | J22: =VLOOKUP(C22,'base de datos'!L22:M1233,2,FALSE) -> Smag | K22: 21
A23: 22 | B23: 22 | C23: =D23&G23 -> 4Bezalel Mendoza | D23: 4 | E23: Preventivo | F23: Alta | G23: Bezalel Mendoza | H23: Electricista | I23: 46049.649 | J23: =VLOOKUP(C23,'base de datos'!L23:M1234,2,FALSE) -> Ishin | K23: 22
A24: 23 | B24: 23 | C24: =D24&G24 -> 5Bezalel Mendoza | D24: 5 | E24: Preventivo | F24: Alta | G24: Bezalel Mendoza | H24: Electricista | I24: 46050.649 | J24: =VLOOKUP(C24,'base de datos'!L24:M1235,2,FALSE) -> Golden Smart 220 | K24: 23
A25: 24 | B25: 24 | C25: =D25&G25 -> 10Bezalel Mendoza | D25: 10 | E25: Preventivo | F25: Alta | G25: Bezalel Mendoza | H25: Electricista | I25: 46051.649 | J25: =VLOOKUP(C25,'base de datos'!L25:M1236,2,FALSE) -> Golden Smart 220 | K25: 24
A26: 25 | B26: 25 | C26: =D26&G26 -> 19Bezalel Mendoza | D26: 19 | E26: Preventivo | F26: Alta | G26: Bezalel Mendoza | H26: Electricista | I26: 46052.649 | J26: =VLOOKUP(C26,'base de datos'!L26:M1237,2,FALSE) -> Ishin | K26: 25
A27: 26 | B27: 26 | C27: =D27&G27 -> 20Bezalel Mendoza | D27: 20 | E27: Preventivo | F27: Alta | G27: Bezalel Mendoza | H27: Electricista | I27: 46053.649 | J27: =VLOOKUP(C27,'base de datos'!L27:M1238,2,FALSE) -> Compresores | K27: 26
A28: 27 | B28: 27 | C28: =D28&G28 -> 21Bezalel Mendoza | D28: 21 | E28: Preventivo | F28: Alta | G28: Bezalel Mendoza | H28: Electricista | I28: 46054.649 | J28: =VLOOKUP(C28,'base de datos'!L28:M1239,2,FALSE) -> Compresores | K28: 27
A29: 28 | B29: 28 | C29: =D29&G29 -> 23Bezalel Mendoza | D29: 23 | E29: Preventivo | F29: Alta | G29: Bezalel Mendoza | H29: Electricista | I29: 46055.649 | J29: =VLOOKUP(C29,'base de datos'!L29:M1240,2,FALSE) -> Bibra | K29: 28
A30: 29 | B30: 29 | C30: =D30&G30 -> 25Bezalel Mendoza | D30: 25 | E30: Preventivo | F30: Alta | G30: Bezalel Mendoza | H30: Electricista | I30: 46056.649 | J30: =VLOOKUP(C30,'base de datos'!L30:M1241,2,FALSE) -> CNC 3 | K30: 29
... A222: 221 | B222: 221 | C222: =D222&G222 -> 156Willy Chic | D222: 156 | E222: Preventivo | F222: Alta | G222: Willy Chic | H222: Mecánico | I222: 46248.649 | J222: =VLOOKUP(C222,'base de datos'!L222:M1433,2,FALSE) -> Bibra | K222: 221

Sheet general
B2: Equipo | C2: frecuencia | D2: Actividad | E2: Prioridad | F2: Duración | G2: Area | H2: Linea 1 | I2: Linea 2 | J2: Linea 3 | K2: Linea 4 | L2: Linea 5
B3: Aplicador de Barniz Liquido | C3: 1 año | D3: Apretar zonas de transición de corriente atornilladas | E3: Alta | F3: 00 h 30 m | G3: lineas Automaticas | H3: Soudronic | I3: Smag | J3: Golden 220 | K3: Golden 110 | L3: Ishin
B4: Aplicador de Barniz Liquido | C4: 1 día | D4: Limpieza de aplicador de barniz | E4: Alta | F4: 00 h 05 m | G4: lineas Automaticas | H4: Soudronic | I4: Smag | J4: Golden 220 | K4: Golden 110 | L4: Ishin
B5: Aplicador de Barniz Liquido | C5: 1 mes | D5: Limpieza de guías, poleas y rodamientos de cintas transporte | E5: Alta | F5: 00 h 05 m | G5: lineas Automaticas | H5: Soudronic | I5: Smag | J5: Golden 220 | K5: Golden 110 | L5: Ishin
B6: Aplicador de Barniz Liquido | C6: 1 año | D6: Limpieza de mandos electrónicos | E6: Alta | F6: 00 h 30 m | G6: lineas Automaticas | H6: Soudronic | I6: Smag | J6: Golden 220 | K6: Golden 110 | L6: Ishin
B7: Aplicador de Barniz Liquido | C7: 1 año | D7: Limpieza general de paneles eléctricos | E7: Media | F7: 00 h 30 m | G7: lineas Automaticas | H7: Soudronic | I7: Smag | J7: Golden 220 | K7: Golden 110 | L7: Ishin
B8: Aplicador de Barniz Liquido | C8: 1 semana | D8: Lubricacion general | E8: Alta | F8: 00 h 05 m | G8: lineas Automaticas | H8: Soudronic | I8: Smag | J8: Golden 220 | K8: Golden 110 | L8: Ishin
B9: Aplicador de Barniz Liquido | C9: 1 año | D9: Revisión de motor | E9: Alta | F9: 00 h 30 m | G9: lineas Automaticas | H9: Soudronic | I9: Smag | J9: Golden 220 | K9: Golden 110 | L9: Ishin
B10: Aplicador de Barniz Liquido | C10: 1 semana | D10: Verificación de fugas en el sistema neumático | E10: Media | F10: 00 h 05 m | G10: lineas Automaticas | H10: Soudronic | I10: Smag | J10: Golden 220 | K10: Golden 110 | L10: Ishin
B11: Aplicador de Barniz polvo | C11: 1 año | D11: Apretar zonas de transición de corriente atornilladas | E11: Alta | F11: 01 h 00 m | G11: lineas Automaticas | H11: Soudronic | I11: Smag | J11: Golden 220 | K11: Golden 110 | L11: No aplica
B12: Aplicador de Barniz polvo | C12: 1 día | D12: Limpieza de brazo aplicador de polvo | E12: Alta | F12: 00 h 02 m | G12: lineas Automaticas | H12: Soudronic | I12: Smag | J12: Golden 220 | K12: Golden 110 | L12: No aplica
B13: Aplicador de Barniz polvo | C13: 2 mes | D13: Limpieza de filtros de bomba de bacio | E13: Alta | F13: 01 h 00 m | G13: lineas Automaticas | H13: Soudronic | I13: Smag | J13: Golden 220 | K13: Golden 110 | L13: No aplica
... B246: venadora | C246: 1 mes | D246: Verificación de cadena de rodillos | E246: Alta | F246: 01 h 00 m | G246: lineas Automaticas | H246: No Aplica | I246: No Aplica | J246: No Aplica | K246: No Aplica | L246: Ishin
B247: Verificadora de fugas | C247: 1 mes | D247: Comprobación y Verificación de bandas de entrada | E247: #VALUE! | F247: 00 h 00 m | G247: lineas Automaticas | H247: Envase Rectangular | I247: No Aplica | J247: No Aplica | K247: No Aplica | L247: No aplica
B248: Verificadora de fugas | C248: 2 día | D248: Comprobación y Verificación de bandas de transición | E248: #VALUE! | F248: 00 h 00 m | G248: lineas Automaticas | H248: Envase Rectangular | I248: No Aplica | J248: No Aplica | K248: No Aplica | L248: No aplica
B249: Verificadora de fugas | C249: 1 mes | D249: Comprobación y Verificación de boquillas de presión de aire | E249: #VALUE! | F249: 00 h 00 m | G249: lineas Automaticas | H249: Envase Rectangular | I249: No Aplica | J249: No Aplica | K249: No Aplica | L249: No aplica
B250: Verificadora de fugas | C250: 1 mes | D250: Limpieza de mandos electricos | E250: #VALUE! | F250: 00 h 00 m | G250: lineas Automaticas | H250: Envase Rectangular | I250: No Aplica | J250: No Aplica | K250: No Aplica | L250: No aplica
B251: Verificadora de fugas | C251: 1 mes | D251: Limpieza General de paneles electricos | E251: #VALUE! | F251: 00 h 00 m | G251: lineas Automaticas | H251: Envase Rectangular | I251: No Aplica | J251: No Aplica | K251: No Aplica | L251: No aplica
B252: Verificadora de fugas | C252: 1 semana | D252: Lubricación de cadena motriz | E252: #VALUE! | F252: 00 h 00 m | G252: lineas Automaticas | H252: Envase Rectangular | I252: No Aplica | J252: No Aplica | K252: No Aplica | L252: No aplica
B253: Verificadora de fugas | C253: 2 día | D253: Verificación de fugas del sistema neumatico | E253: #VALUE! | F253: 00 h 20 m | G253: lineas Automaticas | H253: Envase Rectangular | I253: No Aplica | J253: No Aplica | K253: No Aplica | L253: No aplica
B254: Verificadora de fugas | C254: 2 día | D254: Verificacion de funcionamiento de cilindros neumaticos | E254: #VALUE! | F254: 00 h 00 m | G254: lineas Automaticas | H254: Envase Rectangular | I254: No Aplica | J254: No Aplica | K254: No Aplica | L254: No aplica
B255: Verificadora de fugas | C255: 2 día | D255: Verificacion de tensión de cadena motriz | E255: #VALUE! | F255: 00 h 00 m | G255: lineas Automaticas | H255: Envase Rectangular | I255: No Aplica | J255: No Aplica | K255: No Aplica | L255: No aplica
B256: Alimentador | C256: 1 año | D256: Apretar zonas de transición de corriente atornilladas | E256: Alta | F256: 01 h 00 m | G256: prensas automaticas | H256: BIBRA | I256: CNC 2 | J256: CNC 3 | K256: No Aplica | L256: No aplica
B257: Alimentador | C257: 1 semana | D257: Comprobación de fugas en el sistema neumático e hidráulico | E257: Alta | F257: 00 h 30 m | G257: prensas automaticas | H257: BIBRA | I257: CNC 2 | J257: CNC 3 | K257: No Aplica | L257: No aplica
B258: Alimentador | C258: 2 mes | D258: Engrasado de guía circular de la mesa de alineación | E258: Alta | F258: 00 h 20 m | G258: prensas automaticas | H258: BIBRA | I258: CNC 2 | J258: CNC 3 | K258: No Aplica | L258: No aplica
B259: Alimentador | C259: 1 día | D259: Limpieza de apilador de laminas | E259: Alta | F259: 00 h 02 m | G259: prensas automaticas | H259: BIBRA | I259: CNC 2 | J259: CNC 3 | K259: No Aplica | L259: No aplica
B260: Alimentador | C260: 1 día | D260: Limpieza de brazos de sujeción de láminas | E260: Alta | F260: 00 h 02 m | G260: prensas automaticas | H260: BIBRA | I260: CNC 2 | J260: CNC 3 | K260: No Aplica | L260: No aplica
B261: Alimentador | C261: 1 año | D261: Limpieza de mandos electrónicos | E261: Alta | F261: 01 h 00 m | G261: prensas automaticas | H261: BIBRA | I261: CNC 2 | J261: CNC 3 | K261: No Aplica | L261: No aplica
B262: Alimentador | C262: 1 año | D262: Limpieza general de paneles eléctricos | E262: Alta | F262: 01 h 00 m | G262: prensas automaticas | H262: BIBRA | I262: CNC 2 | J262: CNC 3 | K262: No Aplica | L262: No aplica
B263: Alimentador | C263: 1 mes | D263: Lubricacion de transportador de entrada | E263: Alta | F263: 00 h 25 m | G263: prensas automaticas | H263: BIBRA | I263: CNC 2 | J263: CNC 3 | K263: No Aplica | L263: No aplica
B264: Alimentador | C264: 1 año | D264: Revisión de bomba de lubricación e hidráulico | E264: Alta | F264: 01 h 20 m | G264: prensas automaticas | H264: BIBRA | I264: CNC 2 | J264: CNC 3 | K264: No Aplica | L264: No aplica
B265: Alimentador | C265: 1 año | D265: Revisión de motores | E265: Alta | F265: 01 h 20 m | G265: prensas automaticas | H265: BIBRA | I265: CNC 2 | J265: CNC 3 | K265: No Aplica | L265: No aplica
B266: Alimentador | C266: 2 mes | D266: Revisión y comprobación de elevador de láminas | E266: Alta | F266: 00 h 20 m | G266: prensas automaticas | H266: BIBRA | I266: CNC 2 | J266: CNC 3 | K266: No Aplica | L266: No aplica
B267: Alimentador | C267: 1 mes | D267: Verificación de nivel de aceite hidráulico | E267: Alta | F267: 00 h 10 m | G267: prensas automaticas | H267: BIBRA | I267: CNC 2 | J267: CNC 3 | K267: No Aplica | L267: No aplica
... B368: Montacargas | C368: 1 semana | D368: Verificar nivel de aceite, agregar de ser necesario | E368: Alta | F368: 00 h 02 m | G368: Equipos Auxiliares | H368: Xilin 1 | I368: No Aplica | J368: No Aplica | K368: No Aplica | L368: No aplica

Sheet Actividades
A1: numero_ot | B1: codigo_actividad | C1: Prioridad | D1: id | E1: frecuencia_new | F1: dia_semana | G1: semana_mes | H1: mes | I1: dia_mes | J1: actividad | K1: duracion | L1: Duración | M1: Area | N1: Linea | O1: Resposable | P1: observaciones | Q1: fecha_creacion | R1: frecuencia | V1: aux | W1: numero_ot
A2: =VLOOKUP(T2,$V$2:$W$222,2,FALSE) -> 28 | B2: AS01 | C2: Alta | D2: 23 | E2: =IF(Tabla142[[#This Row],[frecuencia]]="1 año","Anual",IF(Tabla142[[#This Row],[frecuencia]]="1 semana","Semanal",IF(Tabla142[[#This Row],[frecuencia]]="Quincenal",Tabla142[[#This Row],[frecuencia]],IF(Tabla142[[#This Row],[frecuencia]]="1 mes","Mensual",IF(Tabla142[[#This Row],[frecuencia]]="3 mes","Trimestral",IF(Tabla142[[#This Row],[frecuencia]]="6 mes","Semestral",IF(Tabla142[[#This Row],[frecuencia]]="1 día","Diaria",IF(Tabla142[[#This Row],[frecuencia]]="1 mes(es)","Mensual",IF(Tabla142[[#This Row],[frecuencia]]="1 semana(s)","Semanal","Horas"))))))))) -> Anual | F2: =IF(Tabla142[[#This Row],[frecuencia_new]]="Diaria"," ",RANDBETWEEN(1,6)) -> 5 | G2: =IF(Tabla142[[#This Row],[frecuencia_new]]="Diaria","",IF(Tabla142[[#This Row],[frecuencia_new]]="Semanal","",IF(Tabla142[[#This Row],[frecuencia_new]]="Quincenal",RANDBETWEEN(1,2),RANDBETWEEN(1,4)))) -> 1 | H2: =IF(Tabla142[[#This Row],[frecuencia_new]]="Trimestral",RANDBETWEEN(1,3),IF(Tabla142[[#This Row],[frecuencia_new]]="Semestral",RANDBETWEEN(1,6),IF(Tabla142[[#This Row],[frecuencia_new]]="Anual",RANDBETWEEN(1,12),""))) -> 9 | J2: Apretar zonas de transición de corriente atornilladas | K2: =SUM(MID(Tabla142[[#This Row],[Duración]],1,2)*60,MID(Tabla142[[#This Row],[Duración]],6,2)) -> 60 | L2: 01 h 00 m | M2: prensas automaticas | N2: Bibra | O2: Bezalel Mendoza | P2: Electricista | Q2: 46032.649 | R2: 1 año | T2: 23Bezalel Mendoza | V2: 1Alexander Rabanales | W2: 1
A3: =VLOOKUP(T3,$V$2:$W$222,2,FALSE) -> 28 | B3: AS02 | C3: Alta | D3: 23 | E3: =IF(Tabla142[[#This Row],[frecuencia]]="1 año","Anual",IF(Tabla142[[#This Row],[frecuencia]]="1 semana","Semanal",IF(Tabla142[[#This Row],[frecuencia]]="Quincenal",Tabla142[[#This Row],[frecuencia]],IF(Tabla142[[#This Row],[frecuencia]]="1 mes","Mensual",IF(Tabla142[[#This Row],[frecuencia]]="3 mes","Trimestral",IF(Tabla142[[#This Row],[frecuencia]]="6 mes","Semestral",IF(Tabla142[[#This Row],[frecuencia]]="1 día","Diaria",IF(Tabla142[[#This Row],[frecuencia]]="1 mes(es)","Mensual",IF(Tabla142[[#This Row],[frecuencia]]="1 semana(s)","Semanal","Horas"))))))))) -> Anual | F3: =IF(Tabla142[[#This Row],[frecuencia_new]]="Diaria"," ",RANDBETWEEN(1,6)) -> 2 | G3: =IF(Tabla142[[#This Row],[frecuencia_new]]="Diaria","",IF(Tabla142[[#This Row],[frecuencia_new]]="Semanal","",IF(Tabla142[[#This Row],[frecuencia_new]]="Quincenal",RANDBETWEEN(1,2),RANDBETWEEN(1,4)))) -> 4 | H3: =IF(Tabla142[[#This Row],[frecuencia_new]]="Trimestral",RANDBETWEEN(1,3),IF(Tabla142[[#This Row],[frecuencia_new]]="Semestral",RANDBETWEEN(1,6),IF(Tabla142[[#This Row],[frecuencia_new]]="Anual",RANDBETWEEN(1,12),""))) -> 10 | J3: Limpieza de mandos electrónicos | K3: =SUM(MID(Tabla142[[#This Row],[Duración]],1,2)*60,MID(Tabla142[[#This Row],[Duración]],6,2)) -> 60 | L3: 01 h 00 m | M3: prensas automaticas | N3: Bibra | O3: Bezalel Mendoza | P3: Electricista | Q3: 46032.649 | R3: 1 año | T3: 23Bezalel Mendoza | V3: 6Alexander Rabanales | W3: 2
A4: =VLOOKUP(T4,$V$2:$W$222,2,FALSE) -> 28 | B4: AS03 | C4: Alta | D4: 23 | E4: =IF(Tabla142[[#This Row],[frecuencia]]="1 año","Anual",IF(Tabla142[[#This Row],[frecuencia]]="1 semana","Semanal",IF(Tabla142[[#This Row],[frecuencia]]="Quincenal",Tabla142[[#This Row],[frecuencia]],IF(Tabla142[[#This Row],[frecuencia]]="1 mes","Mensual",IF(Tabla142[[#This Row],[frecuencia]]="3 mes","Trimestral",IF(Tabla142[[#This Row],[frecuencia]]="6 mes","Semestral",IF(Tabla142[[#This Row],[frecuencia]]="1 día","Diaria",IF(Tabla142[[#This Row],[frecuencia]]="1 mes(es)","Mensual",IF(Tabla142[[#This Row],[frecuencia]]="1 semana(s)","Semanal","Horas"))))))))) -> Anual | F4: =IF(Tabla142[[#This Row],[frecuencia_new]]="Diaria"," ",RANDBETWEEN(1,6)) -> 3 | G4: =IF(Tabla142[[#This Row],[frecuencia_new]]="Diaria","",IF(Tabla142[[#This Row],[frecuencia_new]]="Semanal","",IF(Tabla142[[#This Row],[frecuencia_new]]="Quincenal",RANDBETWEEN(1,2),RANDBETWEEN(1,4)))) -> 4 | H4: =IF(Tabla142[[#This Row],[frecuencia_new]]="Trimestral",RANDBETWEEN(1,3),IF(Tabla142[[#This Row],[frecuencia_new]]="Semestral",RANDBETWEEN(1,6),IF(Tabla142[[#This Row],[frecuencia_new]]="Anual",RANDBETWEEN(1,12),""))) -> 11 | J4: Limpieza general de paneles eléctricos | K4: =SUM(MID(Tabla142[[#This Row],[Duración]],1,2)*60,MID(Tabla142[[#This Row],[Duración]],6,2)) -> 60 | L4: 01 h 00 m | M4: prensas automaticas | N4: Bibra | O4: Bezalel Mendoza | P4: Electricista | Q4: 46032.649 | R4: 1 año | T4: 23Bezalel Mendoza | V4: 49Alexander Rabanales | W4: 3
A5: =VLOOKUP(T5,$V$2:$W$222,2,FALSE) -> 28 | B5: AS04 | C5: Alta | D5: 23 | E5: =IF(Tabla142[[#This Row],[frecuencia]]="1 año","Anual",IF(Tabla142[[#This Row],[frecuencia]]="1 semana","Semanal",IF(Tabla142[[#This Row],[frecuencia]]="Quincenal",Tabla142[[#This Row],[frecuencia]],IF(Tabla142[[#This Row],[frecuencia]]="1 mes","Mensual",IF(Tabla142[[#This Row],[frecuencia]]="3 mes","Trimestral",IF(Tabla142[[#This Row],[frecuencia]]="6 mes","Semestral",IF(Tabla142[[#This Row],[frecuencia]]="1 día","Diaria",IF(Tabla142[[#This Row],[frecuencia]]="1 mes(es)","Mensual",IF(Tabla142[[#This Row],[frecuencia]]="1 semana(s)","Semanal","Horas"))))))))) -> Anual | F5: =IF(Tabla142[[#This Row],[frecuencia_new]]="Diaria"," ",RANDBETWEEN(1,6)) -> 1 | G5: =IF(Tabla142[[#This Row],[frecuencia_new]]="Diaria","",IF(Tabla142[[#This Row],[frecuencia_new]]="Semanal","",IF(Tabla142[[#This Row],[frecuencia_new]]="Quincenal",RANDBETWEEN(1,2),RANDBETWEEN(1,4)))) -> 2 | H5: =IF(Tabla142[[#This Row],[frecuencia_new]]="Trimestral",RANDBETWEEN(1,3),IF(Tabla142[[#This Row],[frecuencia_new]]="Semestral",RANDBETWEEN(1,6),IF(Tabla142[[#This Row],[frecuencia_new]]="Anual",RANDBETWEEN(1,12),""))) -> 7 | J5: Revisión de bomba de lubricación e hidráulico | K5: =SUM(MID(Tabla142[[#This Row],[Duración]],1,2)*60,MID(Tabla142[[#This Row],[Duración]],6,2)) -> 80 | L5: 01 h 20 m | M5: prensas automaticas | N5: Bibra | O5: Bezalel Mendoza | P5: Electricista | Q5: 46032.649 | R5: 1 año | T5: 23Bezalel Mendoza | V5: 123Andres Rabanales | W5: 4
A6: =VLOOKUP(T6,$V$2:$W$222,2,FALSE) -> 28 | B6: AS05 | C6: Alta | D6: 23 | E6: =IF(Tabla142[[#This Row],[frecuencia]]="1 año","Anual",IF(Tabla142[[#This Row],[frecuencia]]="1 semana","Semanal",IF(Tabla142[[#This Row],[frecuencia]]="Quincenal",Tabla142[[#This Row],[frecuencia]],IF(Tabla142[[#This Row],[frecuencia]]="1 mes","Mensual",IF(Tabla142[[#This Row],[frecuencia]]="3 mes","Trimestral",IF(Tabla142[[#This Row],[frecuencia]]="6 mes","Semestral",IF(Tabla142[[#This Row],[frecuencia]]="1 día","Diaria",IF(Tabla142[[#This Row],[frecuencia]]="1 mes(es)","Mensual",IF(Tabla142[[#This Row],[frecuencia]]="1 semana(s)","Semanal","Horas"))))))))) -> Anual | F6: =IF(Tabla142[[#This Row],[frecuencia_new]]="Diaria"," ",RANDBETWEEN(1,6)) -> 2 | G6: =IF(Tabla142[[#This Row],[frecuencia_new]]="Diaria","",IF(Tabla142[[#This Row],[frecuencia_new]]="Semanal","",IF(Tabla142[[#This Row],[frecuencia_new]]="Quincenal",RANDBETWEEN(1,2),RANDBETWEEN(1,4)))) -> 3 | H6: =IF(Tabla142[[#This Row],[frecuencia_new]]="Trimestral",RANDBETWEEN(1,3),IF(Tabla142[[#This Row],[frecuencia_new]]="Semestral",RANDBETWEEN(1,6),IF(Tabla142[[#This Row],[frecuencia_new]]="Anual",RANDBETWEEN(1,12),""))) -> 6 | J6: Revisión de motores | K6: =SUM(MID(Tabla142[[#This Row],[Duración]],1,2)*60,MID(Tabla142[[#This Row],[Duración]],6,2)) -> 80 | L6: 01 h 20 m | M6: prensas automaticas | N6: Bibra | O6: Bezalel Mendoza | P6: Electricista | Q6: 46032.649 | R6: 1 año | T6: 23Bezalel Mendoza | V6: 4Anthony Campos | W6: 5
A7: =VLOOKUP(T7,$V$2:$W$222,2,FALSE) -> 28 | B7: AS06 | C7: Alta | D7: 23 | E7: =IF(Tabla142[[#This Row],[frecuencia]]="1 año","Anual",IF(Tabla142[[#This Row],[frecuencia]]="1 semana","Semanal",IF(Tabla142[[#This Row],[frecuencia]]="Quincenal",Tabla142[[#This Row],[frecuencia]],IF(Tabla142[[#This Row],[frecuencia]]="1 mes","Mensual",IF(Tabla142[[#This Row],[frecuencia]]="3 mes","Trimestral",IF(Tabla142[[#This Row],[frecuencia]]="6 mes","Semestral",IF(Tabla142[[#This Row],[frecuencia]]="1 día","Diaria",IF(Tabla142[[#This Row],[frecuencia]]="1 mes(es)","Mensual",IF(Tabla142[[#This Row],[frecuencia]]="1 semana(s)","Semanal","Horas"))))))))) -> Anual | F7: =IF(Tabla142[[#This Row],[frecuencia_new]]="Diaria"," ",RANDBETWEEN(1,6)) -> 2 | G7: =IF(Tabla142[[#This Row],[frecuencia_new]]="Diaria","",IF(Tabla142[[#This Row],[frecuencia_new]]="Semanal","",IF(Tabla142[[#This Row],[frecuencia_new]]="Quincenal",RANDBETWEEN(1,2),RANDBETWEEN(1,4)))) -> 3 | H7: =IF(Tabla142[[#This Row],[frecuencia_new]]="Trimestral",RANDBETWEEN(1,3),IF(Tabla142[[#This Row],[frecuencia_new]]="Semestral",RANDBETWEEN(1,6),IF(Tabla142[[#This Row],[frecuencia_new]]="Anual",RANDBETWEEN(1,12),""))) -> 12 | J7: Apretar zonas de transición de corriente atornilladas | K7: =SUM(MID(Tabla142[[#This Row],[Duración]],1,2)*60,MID(Tabla142[[#This Row],[Duración]],6,2)) -> 60 | L7: 01 h 00 m | M7: prensas automaticas | N7: Bibra | O7: Bezalel Mendoza | P7: Electricista | Q7: 46032.649 | R7: 1 año | T7: 23Bezalel Mendoza | V7: 19Anthony Campos | W7: 6
A8: =VLOOKUP(T8,$V$2:$W$222,2,FALSE) -> 28 | B8: AS07 | C8: Alta | D8: 23 | E8: =IF(Tabla142[[#This Row],[frecuencia]]="1 año","Anual",IF(Tabla142[[#This Row],[frecuencia]]="1 semana","Semanal",IF(Tabla142[[#This Row],[frecuencia]]="Quincenal",Tabla142[[#This Row],[frecuencia]],IF(Tabla142[[#This Row],[frecuencia]]="1 mes","Mensual",IF(Tabla142[[#This Row],[frecuencia]]="3 mes","Trimestral",IF(Tabla142[[#This Row],[frecuencia]]="6 mes","Semestral",IF(Tabla142[[#This Row],[frecuencia]]="1 día","Diaria",IF(Tabla142[[#This Row],[frecuencia]]="1 mes(es)","Mensual",IF(Tabla142[[#This Row],[frecuencia]]="1 semana(s)","Semanal","Horas"))))))))) -> Anual | F8: =IF(Tabla142[[#This Row],[frecuencia_new]]="Diaria"," ",RANDBETWEEN(1,6)) -> 6 | G8: =IF(Tabla142[[#This Row],[frecuencia_new]]="Diaria","",IF(Tabla142[[#This Row],[frecuencia_new]]="Semanal","",IF(Tabla142[[#This Row],[frecuencia_new]]="Quincenal",RANDBETWEEN(1,2),RANDBETWEEN(1,4)))) -> 3 | H8: =IF(Tabla142[[#This Row],[frecuencia_new]]="Trimestral",RANDBETWEEN(1,3),IF(Tabla142[[#This Row],[frecuencia_new]]="Semestral",RANDBETWEEN(1,6),IF(Tabla142[[#This Row],[frecuencia_new]]="Anual",RANDBETWEEN(1,12),""))) -> 11 | J8: Limpieza de mandos electrónicos | K8: =SUM(MID(Tabla142[[#This Row],[Duración]],1,2)*60,MID(Tabla142[[#This Row],[Duración]],6,2)) -> 60 | L8: 01 h 00 m | M8: prensas automaticas | N8: Bibra | O8: Bezalel Mendoza | P8: Electricista | Q8: 46032.649 | R8: 1 año | T8: 23Bezalel Mendoza | V8: 46Anthony Campos | W8: 7
A9: =VLOOKUP(T9,$V$2:$W$222,2,FALSE) -> 28 | B9: AS08 | C9: Alta | D9: 23 | E9: =IF(Tabla142[[#This Row],[frecuencia]]="1 año","Anual",IF(Tabla142[[#This Row],[frecuencia]]="1 semana","Semanal",IF(Tabla142[[#This Row],[frecuencia]]="Quincenal",Tabla142[[#This Row],[frecuencia]],IF(Tabla142[[#This Row],[frecuencia]]="1 mes","Mensual",IF(Tabla142[[#This Row],[frecuencia]]="3 mes","Trimestral",IF(Tabla142[[#This Row],[frecuencia]]="6 mes","Semestral",IF(Tabla142[[#This Row],[frecuencia]]="1 día","Diaria",IF(Tabla142[[#This Row],[frecuencia]]="1 mes(es)","Mensual",IF(Tabla142[[#This Row],[frecuencia]]="1 semana(s)","Semanal","Horas"))))))))) -> Anual | F9: =IF(Tabla142[[#This Row],[frecuencia_new]]="Diaria"," ",RANDBETWEEN(1,6)) -> 3 | G9: =IF(Tabla142[[#This Row],[frecuencia_new]]="Diaria","",IF(Tabla142[[#This Row],[frecuencia_new]]="Semanal","",IF(Tabla142[[#This Row],[frecuencia_new]]="Quincenal",RANDBETWEEN(1,2),RANDBETWEEN(1,4)))) -> 2 | H9: =IF(Tabla142[[#This Row],[frecuencia_new]]="Trimestral",RANDBETWEEN(1,3),IF(Tabla142[[#This Row],[frecuencia_new]]="Semestral",RANDBETWEEN(1,6),IF(Tabla142[[#This Row],[frecuencia_new]]="Anual",RANDBETWEEN(1,12),""))) -> 8 | J9: Limpieza general de paneles eléctricos | K9: =SUM(MID(Tabla142[[#This Row],[Duración]],1,2)*60,MID(Tabla142[[#This Row],[Duración]],6,2)) -> 60 | L9: 01 h 00 m | M9: prensas automaticas | N9: Bibra | O9: Bezalel Mendoza | P9: Electricista | Q9: 46032.649 | R9: 1 año | T9: 23Bezalel Mendoza | V9: 47Anthony Campos | W9: 8
A10: =VLOOKUP(T10,$V$2:$W$222,2,FALSE) -> 28 | B10: AS09 | C10: Alta | D10: 23 | E10: =IF(Tabla142[[#This Row],[frecuencia]]="1 año","Anual",IF(Tabla142[[#This Row],[frecuencia]]="1 semana","Semanal",IF(Tabla142[[#This Row],[frecuencia]]="Quincenal",Tabla142[[#This Row],[frecuencia]],IF(Tabla142[[#This Row],[frecuencia]]="1 mes","Mensual",IF(Tabla142[[#This Row],[frecuencia]]="3 mes","Trimestral",IF(Tabla142[[#This Row],[frecuencia]]="6 mes","Semestral",IF(Tabla142[[#This Row],[frecuencia]]="1 día","Diaria",IF(Tabla142[[#This Row],[frecuencia]]="1 mes(es)","Mensual",IF(Tabla142[[#This Row],[frecuencia]]="1 semana(s)","Semanal","Horas"))))))))) -> Anual | F10: =IF(Tabla142[[#This Row],[frecuencia_new]]="Diaria"," ",RANDBETWEEN(1,6)) -> 1 | G10: =IF(Tabla142[[#This Row],[frecuencia_new]]="Diaria","",IF(Tabla142[[#This Row],[frecuencia_new]]="Semanal","",IF(Tabla142[[#This Row],[frecuencia_new]]="Quincenal",RANDBETWEEN(1,2),RANDBETWEEN(1,4)))) -> 3 | H10: =IF(Tabla142[[#This Row],[frecuencia_new]]="Trimestral",RANDBETWEEN(1,3),IF(Tabla142[[#This Row],[frecuencia_new]]="Semestral",RANDBETWEEN(1,6),IF(Tabla142[[#This Row],[frecuencia_new]]="Anual",RANDBETWEEN(1,12),""))) -> 2 | J10: Revisión de bomba de lubricación e hidráulico | K10: =SUM(MID(Tabla142[[#This Row],[Duración]],1,2)*60,MID(Tabla142[[#This Row],[Duración]],6,2)) -> 80 | L10: 01 h 20 m | M10: prensas automaticas | N10: Bibra | O10: Bezalel Mendoza | P10: Electricista | Q10: 46032.649 | R10: 1 año | T10: 23Bezalel Mendoza | V10: 52Anthony Campos | W10: 9
A11: =VLOOKUP(T11,$V$2:$W$222,2,FALSE) -> 28 | B11: AS10 | C11: Alta | D11: 23 | E11: =IF(Tabla142[[#This Row],[frecuencia]]="1 año","Anual",IF(Tabla142[[#This Row],[frecuencia]]="1 semana","Semanal",IF(Tabla142[[#This Row],[frecuencia]]="Quincenal",Tabla142[[#This Row],[frecuencia]],IF(Tabla142[[#This Row],[frecuencia]]="1 mes","Mensual",IF(Tabla142[[#This Row],[frecuencia]]="3 mes","Trimestral",IF(Tabla142[[#This Row],[frecuencia]]="6 mes","Semestral",IF(Tabla142[[#This Row],[frecuencia]]="1 día","Diaria",IF(Tabla142[[#This Row],[frecuencia]]="1 mes(es)","Mensual",IF(Tabla142[[#This Row],[frecuencia]]="1 semana(s)","Semanal","Horas"))))))))) -> Anual | F11: =IF(Tabla142[[#This Row],[frecuencia_new]]="Diaria"," ",RANDBETWEEN(1,6)) -> 4 | G11: =IF(Tabla142[[#This Row],[frecuencia_new]]="Diaria","",IF(Tabla142[[#This Row],[frecuencia_new]]="Semanal","",IF(Tabla142[[#This Row],[frecuencia_new]]="Quincenal",RANDBETWEEN(1,2),RANDBETWEEN(1,4)))) -> 3 | H11: =IF(Tabla142[[#This Row],[frecuencia_new]]="Trimestral",RANDBETWEEN(1,3),IF(Tabla142[[#This Row],[frecuencia_new]]="Semestral",RANDBETWEEN(1,6),IF(Tabla142[[#This Row],[frecuencia_new]]="Anual",RANDBETWEEN(1,12),""))) -> 7 | J11: Revisión de motores | K11: =SUM(MID(Tabla142[[#This Row],[Duración]],1,2)*60,MID(Tabla142[[#This Row],[Duración]],6,2)) -> 80 | L11: 01 h 20 m | M11: prensas automaticas | N11: Bibra | O11: Bezalel Mendoza | P11: Electricista | Q11: 46032.649 | R11: 1 año | T11: 23Bezalel Mendoza | V11: 79Anthony Campos | W11: 10
A12: =VLOOKUP(T12,$V$2:$W$222,2,FALSE) -> 28 | B12: AS11 | C12: Alta | D12: 23 | E12: =IF(Tabla142[[#This Row],[frecuencia]]="1 año","Anual",IF(Tabla142[[#This Row],[frecuencia]]="1 semana","Semanal",IF(Tabla142[[#This Row],[frecuencia]]="Quincenal",Tabla142[[#This Row],[frecuencia]],IF(Tabla142[[#This Row],[frecuencia]]="1 mes","Mensual",IF(Tabla142[[#This Row],[frecuencia]]="3 mes","Trimestral",IF(Tabla142[[#This Row],[frecuencia]]="6 mes","Semestral",IF(Tabla142[[#This Row],[frecuencia]]="1 día","Diaria",IF(Tabla142[[#This Row],[frecuencia]]="1 mes(es)","Mensual",IF(Tabla142[[#This Row],[frecuencia]]="1 semana(s)","Semanal","Horas"))))))))) -> Anual | F12: =IF(Tabla142[[#This Row],[frecuencia_new]]="Diaria"," ",RANDBETWEEN(1,6)) -> 1 | G12: =IF(Tabla142[[#This Row],[frecuencia_new]]="Diaria","",IF(Tabla142[[#This Row],[frecuencia_new]]="Semanal","",IF(Tabla142[[#This Row],[frecuencia_new]]="Quincenal",RANDBETWEEN(1,2),RANDBETWEEN(1,4)))) -> 3 | H12: =IF(Tabla142[[#This Row],[frecuencia_new]]="Trimestral",RANDBETWEEN(1,3),IF(Tabla142[[#This Row],[frecuencia_new]]="Semestral",RANDBETWEEN(1,6),IF(Tabla142[[#This Row],[frecuencia_new]]="Anual",RANDBETWEEN(1,12),""))) -> 3 | J12: Apretar zonas de transición de corriente atornilladas | K12: =SUM(MID(Tabla142[[#This Row],[Duración]],1,2)*60,MID(Tabla142[[#This Row],[Duración]],6,2)) -> 60 | L12: 01 h 00 m | M12: prensas automaticas | N12: Bibra | O12: Bezalel Mendoza | P12: Electricista | Q12: 46032.649 | R12: 1 año | T12: 23Bezalel Mendoza | V12: 106Anthony Campos | W12: 11
A13: =VLOOKUP(T13,$V$2:$W$222,2,FALSE) -> 28 | B13: AS12 | C13: Alta | D13: 23 | E13: =IF(Tabla142[[#This Row],[frecuencia]]="1 año","Anual",IF(Tabla142[[#This Row],[frecuencia]]="1 semana","Semanal",IF(Tabla142[[#This Row],[frecuencia]]="Quincenal",Tabla142[[#This Row],[frecuencia]],IF(Tabla142[[#This Row],[frecuencia]]="1 mes","Mensual",IF(Tabla142[[#This Row],[frecuencia]]="3 mes","Trimestral",IF(Tabla142[[#This Row],[frecuencia]]="6 mes","Semestral",IF(Tabla142[[#This Row],[frecuencia]]="1 día","Diaria",IF(Tabla142[[#This Row],[frecuencia]]="1 mes(es)","Mensual",IF(Tabla142[[#This Row],[frecuencia]]="1 semana(s)","Semanal","Horas"))))))))) -> Anual | F13: =IF(Tabla142[[#This Row],[frecuencia_new]]="Diaria"," ",RANDBETWEEN(1,6)) -> 5 | G13: =IF(Tabla142[[#This Row],[frecuencia_new]]="Diaria","",IF(Tabla142[[#This Row],[frecuencia_new]]="Semanal","",IF(Tabla142[[#This Row],[frecuencia_new]]="Quincenal",RANDBETWEEN(1,2),RANDBETWEEN(1,4)))) -> 3 | H13: =IF(Tabla142[[#This Row],[frecuencia_new]]="Trimestral",RANDBETWEEN(1,3),IF(Tabla142[[#This Row],[frecuencia_new]]="Semestral",RANDBETWEEN(1,6),IF(Tabla142[[#This Row],[frecuencia_new]]="Anual",RANDBETWEEN(1,12),""))) -> 7 | J13: Limpieza de mandos electrónicos | K13: =SUM(MID(Tabla142[[#This Row],[Duración]],1,2)*60,MID(Tabla142[[#This Row],[Duración]],6,2)) -> 60 | L13: 01 h 00 m | M13: prensas automaticas | N13: Bibra | O13: Bezalel Mendoza | P13: Electricista | Q13: 46032.649 | R13: 1 año | T13: 23Bezalel Mendoza | V13: 110Anthony Campos | W13: 12
... A222: =VLOOKUP(T222,$V$2:$W$222,2,FALSE) -> 172 | B222: AS221 | C222: Alta | D222: 98 | E222: =IF(Tabla142[[#This Row],[frecuencia]]="1 año","Anual",IF(Tabla142[[#This Row],[frecuencia]]="1 semana","Semanal",IF(Tabla142[[#This Row],[frecuencia]]="Quincenal",Tabla142[[#This Row],[frecuencia]],IF(Tabla142[[#This Row],[frecuencia]]="1 mes","Mensual",IF(Tabla142[[#This Row],[frecuencia]]="3 mes","Trimestral",IF(Tabla142[[#This Row],[frecuencia]]="6 mes","Semestral",IF(Tabla142[[#This Row],[frecuencia]]="1 día","Diaria",IF(Tabla142[[#This Row],[frecuencia]]="1 mes(es)","Mensual",IF(Tabla142[[#This Row],[frecuencia]]="1 semana(s)","Semanal","Horas"))))))))) -> Diaria | F222: =IF(Tabla142[[#This Row],[frecuencia_new]]="Diaria"," ",RANDBETWEEN(1,6)) | G222: =IF(Tabla142[[#This Row],[frecuencia_new]]="Diaria","",IF(Tabla142[[#This Row],[frecuencia_new]]="Semanal","",IF(Tabla142[[#This Row],[frecuencia_new]]="Quincenal",RANDBETWEEN(1,2),RANDBETWEEN(1,4)))) | H222: =IF(Tabla142[[#This Row],[frecuencia_new]]="Trimestral",RANDBETWEEN(1,3),IF(Tabla142[[#This Row],[frecuencia_new]]="Semestral",RANDBETWEEN(1,6),IF(Tabla142[[#This Row],[frecuencia_new]]="Anual",RANDBETWEEN(1,12),""))) | J222: Limpieza de los carriles de guía | K222: =SUM(MID(Tabla142[[#This Row],[Duración]],1,2)*60,MID(Tabla142[[#This Row],[Duración]],6,2)) -> 2 | L222: 00 h 02 m | M222: prensas automaticas | N222: CNC 3 | O222: Joel Vasquez | P222: Operador | Q222: 46032.649 | R222: 1 día | T222: 98Joel Vasquez | V222: 156Willy Chic | W222: 221
A223: =VLOOKUP(T223,$V$2:$W$222,2,FALSE) -> 172 | B223: AS222 | C223: Alta | D223: 98 | E223: =IF(Tabla142[[#This Row],[frecuencia]]="1 año","Anual",IF(Tabla142[[#This Row],[frecuencia]]="1 semana","Semanal",IF(Tabla142[[#This Row],[frecuencia]]="Quincenal",Tabla142[[#This Row],[frecuencia]],IF(Tabla142[[#This Row],[frecuencia]]="1 mes","Mensual",IF(Tabla142[[#This Row],[frecuencia]]="3 mes","Trimestral",IF(Tabla142[[#This Row],[frecuencia]]="6 mes","Semestral",IF(Tabla142[[#This Row],[frecuencia]]="1 día","Diaria",IF(Tabla142[[#This Row],[frecuencia]]="1 mes(es)","Mensual",IF(Tabla142[[#This Row],[frecuencia]]="1 semana(s)","Semanal","Horas"))))))))) -> Diaria | F223: =IF(Tabla142[[#This Row],[frecuencia_new]]="Diaria"," ",RANDBETWEEN(1,6)) | G223: =IF(Tabla142[[#This Row],[frecuencia_new]]="Diaria","",IF(Tabla142[[#This Row],[frecuencia_new]]="Semanal","",IF(Tabla142[[#This Row],[frecuencia_new]]="Quincenal",RANDBETWEEN(1,2),RANDBETWEEN(1,4)))) | H223: =IF(Tabla142[[#This Row],[frecuencia_new]]="Trimestral",RANDBETWEEN(1,3),IF(Tabla142[[#This Row],[frecuencia_new]]="Semestral",RANDBETWEEN(1,6),IF(Tabla142[[#This Row],[frecuencia_new]]="Anual",RANDBETWEEN(1,12),""))) | J223: Limpieza de residuos en toda la maquina | K223: =SUM(MID(Tabla142[[#This Row],[Duración]],1,2)*60,MID(Tabla142[[#This Row],[Duración]],6,2)) -> 2 | L223: 00 h 02 m | M223: prensas automaticas | N223: CNC 3 | O223: Joel Vasquez | P223: Operador | Q223: 46032.649 | R223: 1 día | T223: 98Joel Vasquez
A224: =VLOOKUP(T224,$V$2:$W$222,2,FALSE) -> 172 | B224: AS223 | C224: Alta | D224: 98 | E224: =IF(Tabla142[[#This Row],[frecuencia]]="1 año","Anual",IF(Tabla142[[#This Row],[frecuencia]]="1 semana","Semanal",IF(Tabla142[[#This Row],[frecuencia]]="Quincenal",Tabla142[[#This Row],[frecuencia]],IF(Tabla142[[#This Row],[frecuencia]]="1 mes","Mensual",IF(Tabla142[[#This Row],[frecuencia]]="3 mes","Trimestral",IF(Tabla142[[#This Row],[frecuencia]]="6 mes","Semestral",IF(Tabla142[[#This Row],[frecuencia]]="1 día","Diaria",IF(Tabla142[[#This Row],[frecuencia]]="1 mes(es)","Mensual",IF(Tabla142[[#This Row],[frecuencia]]="1 semana(s)","Semanal","Horas"))))))))) -> Diaria | F224: =IF(Tabla142[[#This Row],[frecuencia_new]]="Diaria"," ",RANDBETWEEN(1,6)) | G224: =IF(Tabla142[[#This Row],[frecuencia_new]]="Diaria","",IF(Tabla142[[#This Row],[frecuencia_new]]="Semanal","",IF(Tabla142[[#This Row],[frecuencia_new]]="Quincenal",RANDBETWEEN(1,2),RANDBETWEEN(1,4)))) | H224: =IF(Tabla142[[#This Row],[frecuencia_new]]="Trimestral",RANDBETWEEN(1,3),IF(Tabla142[[#This Row],[frecuencia_new]]="Semestral",RANDBETWEEN(1,6),IF(Tabla142[[#This Row],[frecuencia_new]]="Anual",RANDBETWEEN(1,12),""))) | J224: Limpieza del sistema de rizado | K224: =SUM(MID(Tabla142[[#This Row],[Duración]],1,2)*60,MID(Tabla142[[#This Row],[Duración]],6,2)) -> 2 | L224: 00 h 02 m | M224: prensas automaticas | N224: CNC 3 | O224: Joel Vasquez | P224: Operador | Q224: 46032.649 | R224: 1 día | T224: 98Joel Vasquez
A225: =VLOOKUP(T225,$V$2:$W$222,2,FALSE) -> 213 | B225: AS224 | C225: Alta | D225: 98 | E225: =IF(Tabla142[[#This Row],[frecuencia]]="1 año","Anual",IF(Tabla142[[#This Row],[frecuencia]]="1 semana","Semanal",IF(Tabla142[[#This Row],[frecuencia]]="Quincenal",Tabla142[[#This Row],[frecuencia]],IF(Tabla142[[#This Row],[frecuencia]]="1 mes","Mensual",IF(Tabla142[[#This Row],[frecuencia]]="3 mes","Trimestral",IF(Tabla142[[#This Row],[frecuencia]]="6 mes","Semestral",IF(Tabla142[[#This Row],[frecuencia]]="1 día","Diaria",IF(Tabla142[[#This Row],[frecuencia]]="1 mes(es)","Mensual",IF(Tabla142[[#This Row],[frecuencia]]="1 semana(s)","Semanal","Horas"))))))))) -> Mensual | F225: =IF(Tabla142[[#This Row],[frecuencia_new]]="Diaria"," ",RANDBETWEEN(1,6)) -> 6 | G225: =IF(Tabla142[[#This Row],[frecuencia_new]]="Diaria","",IF(Tabla142[[#This Row],[frecuencia_new]]="Semanal","",IF(Tabla142[[#This Row],[frecuencia_new]]="Quincenal",RANDBETWEEN(1,2),RANDBETWEEN(1,4)))) -> 1 | H225: =IF(Tabla142[[#This Row],[frecuencia_new]]="Trimestral",RANDBETWEEN(1,3),IF(Tabla142[[#This Row],[frecuencia_new]]="Semestral",RANDBETWEEN(1,6),IF(Tabla142[[#This Row],[frecuencia_new]]="Anual",RANDBETWEEN(1,12),""))) | J225: Comprobación y verificación de fajas | K225: =SUM(MID(Tabla142[[#This Row],[Duración]],1,2)*60,MID(Tabla142[[#This Row],[Duración]],6,2)) -> 20 | L225: 00 h 20 m | M225: prensas automaticas | N225: CNC 3 | O225: Raul Castillo | P225: Mecánico | Q225: 46032.649 | R225: 1 mes | T225: 98Raul Castillo
A226: =VLOOKUP(T226,$V$2:$W$222,2,FALSE) -> 213 | B226: AS225 | C226: Alta | D226: 98 | E226: =IF(Tabla142[[#This Row],[frecuencia]]="1 año","Anual",IF(Tabla142[[#This Row],[frecuencia]]="1 semana","Semanal",IF(Tabla142[[#This Row],[frecuencia]]="Quincenal",Tabla142[[#This Row],[frecuencia]],IF(Tabla142[[#This Row],[frecuencia]]="1 mes","Mensual",IF(Tabla142[[#This Row],[frecuencia]]="3 mes","Trimestral",IF(Tabla142[[#This Row],[frecuencia]]="6 mes","Semestral",IF(Tabla142[[#This Row],[frecuencia]]="1 día","Diaria",IF(Tabla142[[#This Row],[frecuencia]]="1 mes(es)","Mensual",IF(Tabla142[[#This Row],[frecuencia]]="1 semana(s)","Semanal","Horas"))))))))) -> Mensual | F226: =IF(Tabla142[[#This Row],[frecuencia_new]]="Diaria"," ",RANDBETWEEN(1,6)) -> 5 | G226: =IF(Tabla142[[#This Row],[frecuencia_new]]="Diaria","",IF(Tabla142[[#This Row],[frecuencia_new]]="Semanal","",IF(Tabla142[[#This Row],[frecuencia_new]]="Quincenal",RANDBETWEEN(1,2),RANDBETWEEN(1,4)))) -> 1 | H226: =IF(Tabla142[[#This Row],[frecuencia_new]]="Trimestral",RANDBETWEEN(1,3),IF(Tabla142[[#This Row],[frecuencia_new]]="Semestral",RANDBETWEEN(1,6),IF(Tabla142[[#This Row],[frecuencia_new]]="Anual",RANDBETWEEN(1,12),""))) | J226: Engrase del rodamiento del disco de rizado | K226: =SUM(MID(Tabla142[[#This Row],[Duración]],1,2)*60,MID(Tabla142[[#This Row],[Duración]],6,2)) -> 20 | L226: 00 h 20 m | M226: prensas automaticas | N226: CNC 3 | O226: Raul Castillo | P226: Mecánico | Q226: 46032.649 | R226: 1 mes | T226: 98Raul Castillo
A227: =VLOOKUP(T227,$V$2:$W$222,2,FALSE) -> 213 | B227: AS226 | C227: Alta | D227: 98 | E227: =IF(Tabla142[[#This Row],[frecuencia]]="1 año","Anual",IF(Tabla142[[#This Row],[frecuencia]]="1 semana","Semanal",IF(Tabla142[[#This Row],[frecuencia]]="Quincenal",Tabla142[[#This Row],[frecuencia]],IF(Tabla142[[#This Row],[frecuencia]]="1 mes","Mensual",IF(Tabla142[[#This Row],[frecuencia]]="3 mes","Trimestral",IF(Tabla142[[#This Row],[frecuencia]]="6 mes","Semestral",IF(Tabla142[[#This Row],[frecuencia]]="1 día","Diaria",IF(Tabla142[[#This Row],[frecuencia]]="1 mes(es)","Mensual",IF(Tabla142[[#This Row],[frecuencia]]="1 semana(s)","Semanal","Horas"))))))))) -> Semanal | F227: =IF(Tabla142[[#This Row],[frecuencia_new]]="Diaria"," ",RANDBETWEEN(1,6)) -> 1 | G227: =IF(Tabla142[[#This Row],[frecuencia_new]]="Diaria","",IF(Tabla142[[#This Row],[frecuencia_new]]="Semanal","",IF(Tabla142[[#This Row],[frecuencia_new]]="Quincenal",RANDBETWEEN(1,2),RANDBETWEEN(1,4)))) | H227: =IF(Tabla142[[#This Row],[frecuencia_new]]="Trimestral",RANDBETWEEN(1,3),IF(Tabla142[[#This Row],[frecuencia_new]]="Semestral",RANDBETWEEN(1,6),IF(Tabla142[[#This Row],[frecuencia_new]]="Anual",RANDBETWEEN(1,12),""))) | J227: Verificación de cojines, rodillos, tensores y sprocket | K227: =SUM(MID(Tabla142[[#This Row],[Duración]],1,2)*60,MID(Tabla142[[#This Row],[Duración]],6,2)) -> 20 | L227: 00 h 20 m | M227: prensas automaticas | N227: CNC 3 | O227: Raul Castillo | P227: Mecánico | Q227: 46032.649 | R227: 1 semana | T227: 98Raul Castillo
A228: =VLOOKUP(T228,$V$2:$W$222,2,FALSE) -> 58 | B228: AS227 | C228: Alta | D228: 145 | E228: =IF(Tabla142[[#This Row],[frecuencia]]="1 año","Anual",IF(Tabla142[[#This Row],[frecuencia]]="1 semana","Semanal",IF(Tabla142[[#This Row],[frecuencia]]="Quincenal",Tabla142[[#This Row],[frecuencia]],IF(Tabla142[[#This Row],[frecuencia]]="1 mes","Mensual",IF(Tabla142[[#This Row],[frecuencia]]="3 mes","Trimestral",IF(Tabla142[[#This Row],[frecuencia]]="6 mes","Semestral",IF(Tabla142[[#This Row],[frecuencia]]="1 día","Diaria",IF(Tabla142[[#This Row],[frecuencia]]="1 mes(es)","Mensual",IF(Tabla142[[#This Row],[frecuencia]]="1 semana(s)","Semanal","Horas"))))))))) -> Anual | F228: =IF(Tabla142[[#This Row],[frecuencia_new]]="Diaria"," ",RANDBETWEEN(1,6)) -> 4 | G228: =IF(Tabla142[[#This Row],[frecuencia_new]]="Diaria","",IF(Tabla142[[#This Row],[frecuencia_new]]="Semanal","",IF(Tabla142[[#This Row],[frecuencia_new]]="Quincenal",RANDBETWEEN(1,2),RANDBETWEEN(1,4)))) -> 4 | H228: =IF(Tabla142[[#This Row],[frecuencia_new]]="Trimestral",RANDBETWEEN(1,3),IF(Tabla142[[#This Row],[frecuencia_new]]="Semestral",RANDBETWEEN(1,6),IF(Tabla142[[#This Row],[frecuencia_new]]="Anual",RANDBETWEEN(1,12),""))) -> 10 | J228: Apretar zonas de transición de corriente atornilladas | K228: =SUM(MID(Tabla142[[#This Row],[Duración]],1,2)*60,MID(Tabla142[[#This Row],[Duración]],6,2)) -> 30 | L228: 00 h 30 m | M228: prensas automaticas | N228: CNC 3 | O228: Bezalel Mendoza | P228: Electricista | Q228: 46032.649 | R228: 1 año | T228: 145Bezalel Mendoza
A229: =VLOOKUP(T229,$V$2:$W$222,2,FALSE) -> 58 | B229: AS228 | C229: Alta | D229: 145 | E229: =IF(Tabla142[[#This Row],[frecuencia]]="1 año","Anual",IF(Tabla142[[#This Row],[frecuencia]]="1 semana","Semanal",IF(Tabla142[[#This Row],[frecuencia]]="Quincenal",Tabla142[[#This Row],[frecuencia]],IF(Tabla142[[#This Row],[frecuencia]]="1 mes","Mensual",IF(Tabla142[[#This Row],[frecuencia]]="3 mes","Trimestral",IF(Tabla142[[#This Row],[frecuencia]]="6 mes","Semestral",IF(Tabla142[[#This Row],[frecuencia]]="1 día","Diaria",IF(Tabla142[[#This Row],[frecuencia]]="1 mes(es)","Mensual",IF(Tabla142[[#This Row],[frecuencia]]="1 semana(s)","Semanal","Horas"))))))))) -> Anual | F229: =IF(Tabla142[[#This Row],[frecuencia_new]]="Diaria"," ",RANDBETWEEN(1,6)) -> 5 | G229: =IF(Tabla142[[#This Row],[frecuencia_new]]="Diaria","",IF(Tabla142[[#This Row],[frecuencia_new]]="Semanal","",IF(Tabla142[[#This Row],[frecuencia_new]]="Quincenal",RANDBETWEEN(1,2),RANDBETWEEN(1,4)))) -> 1 | H229: =IF(Tabla142[[#This Row],[frecuencia_new]]="Trimestral",RANDBETWEEN(1,3),IF(Tabla142[[#This Row],[frecuencia_new]]="Semestral",RANDBETWEEN(1,6),IF(Tabla142[[#This Row],[frecuencia_new]]="Anual",RANDBETWEEN(1,12),""))) -> 3 | J229: Limpieza general de paneles eléctricos | K229: =SUM(MID(Tabla142[[#This Row],[Duración]],1,2)*60,MID(Tabla142[[#This Row],[Duración]],6,2)) -> 30 | L229: 00 h 30 m | M229: prensas automaticas | N229: CNC 3 | O229: Bezalel Mendoza | P229: Electricista | Q229: 46032.649 | R229: 1 año | T229: 145Bezalel Mendoza
A230: =VLOOKUP(T230,$V$2:$W$222,2,FALSE) -> 58 | B230: AS229 | C230: Alta | D230: 145 | E230: =IF(Tabla142[[#This Row],[frecuencia]]="1 año","Anual",IF(Tabla142[[#This Row],[frecuencia]]="1 semana","Semanal",IF(Tabla142[[#This Row],[frecuencia]]="Quincenal",Tabla142[[#This Row],[frecuencia]],IF(Tabla142[[#This Row],[frecuencia]]="1 mes","Mensual",IF(Tabla142[[#This Row],[frecuencia]]="3 mes","Trimestral",IF(Tabla142[[#This Row],[frecuencia]]="6 mes","Semestral",IF(Tabla142[[#This Row],[frecuencia]]="1 día","Diaria",IF(Tabla142[[#This Row],[frecuencia]]="1 mes(es)","Mensual",IF(Tabla142[[#This Row],[frecuencia]]="1 semana(s)","Semanal","Horas"))))))))) -> Anual | F230: =IF(Tabla142[[#This Row],[frecuencia_new]]="Diaria"," ",RANDBETWEEN(1,6)) -> 5 | G230: =IF(Tabla142[[#This Row],[frecuencia_new]]="Diaria","",IF(Tabla142[[#This Row],[frecuencia_new]]="Semanal","",IF(Tabla142[[#This Row],[frecuencia_new]]="Quincenal",RANDBETWEEN(1,2),RANDBETWEEN(1,4)))) -> 2 | H230: =IF(Tabla142[[#This Row],[frecuencia_new]]="Trimestral",RANDBETWEEN(1,3),IF(Tabla142[[#This Row],[frecuencia_new]]="Semestral",RANDBETWEEN(1,6),IF(Tabla142[[#This Row],[frecuencia_new]]="Anual",RANDBETWEEN(1,12),""))) -> 1 | J230: Limpieza los mandos electrónicos | K230: =SUM(MID(Tabla142[[#This Row],[Duración]],1,2)*60,MID(Tabla142[[#This Row],[Duración]],6,2)) -> 30 | L230: 00 h 30 m | M230: prensas automaticas | N230: CNC 3 | O230: Bezalel Mendoza | P230: Electricista | Q230: 46032.649 | R230: 1 año | T230: 145Bezalel Mendoza
A231: =VLOOKUP(T231,$V$2:$W$222,2,FALSE) -> 58 | B231: AS230 | C231: Alta | D231: 145 | E231: =IF(Tabla142[[#This Row],[frecuencia]]="1 año","Anual",IF(Tabla142[[#This Row],[frecuencia]]="1 semana","Semanal",IF(Tabla142[[#This Row],[frecuencia]]="Quincenal",Tabla142[[#This Row],[frecuencia]],IF(Tabla142[[#This Row],[frecuencia]]="1 mes","Mensual",IF(Tabla142[[#This Row],[frecuencia]]="3 mes","Trimestral",IF(Tabla142[[#This Row],[frecuencia]]="6 mes","Semestral",IF(Tabla142[[#This Row],[frecuencia]]="1 día","Diaria",IF(Tabla142[[#This Row],[frecuencia]]="1 mes(es)","Mensual",IF(Tabla142[[#This Row],[frecuencia]]="1 semana(s)","Semanal","Horas"))))))))) -> Anual | F231: =IF(Tabla142[[#This Row],[frecuencia_new]]="Diaria"," ",RANDBETWEEN(1,6)) -> 5 | G231: =IF(Tabla142[[#This Row],[frecuencia_new]]="Diaria","",IF(Tabla142[[#This Row],[frecuencia_new]]="Semanal","",IF(Tabla142[[#This Row],[frecuencia_new]]="Quincenal",RANDBETWEEN(1,2),RANDBETWEEN(1,4)))) -> 4 | H231: =IF(Tabla142[[#This Row],[frecuencia_new]]="Trimestral",RANDBETWEEN(1,3),IF(Tabla142[[#This Row],[frecuencia_new]]="Semestral",RANDBETWEEN(1,6),IF(Tabla142[[#This Row],[frecuencia_new]]="Anual",RANDBETWEEN(1,12),""))) -> 1 | J231: Revisión de motor | K231: =SUM(MID(Tabla142[[#This Row],[Duración]],1,2)*60,MID(Tabla142[[#This Row],[Duración]],6,2)) -> 30 | L231: 00 h 30 m | M231: prensas automaticas | N231: CNC 3 | O231: Bezalel Mendoza | P231: Electricista | Q231: 46032.649 | R231: 1 año | T231: 145Bezalel Mendoza
A232: =VLOOKUP(T232,$V$2:$W$222,2,FALSE) -> 173 | B232: AS231 | C232: Alta | D232: 145 | E232: =IF(Tabla142[[#This Row],[frecuencia]]="1 año","Anual",IF(Tabla142[[#This Row],[frecuencia]]="1 semana","Semanal",IF(Tabla142[[#This Row],[frecuencia]]="Quincenal",Tabla142[[#This Row],[frecuencia]],IF(Tabla142[[#This Row],[frecuencia]]="1 mes","Mensual",IF(Tabla142[[#This Row],[frecuencia]]="3 mes","Trimestral",IF(Tabla142[[#This Row],[frecuencia]]="6 mes","Semestral",IF(Tabla142[[#This Row],[frecuencia]]="1 día","Diaria",IF(Tabla142[[#This Row],[frecuencia]]="1 mes(es)","Mensual",IF(Tabla142[[#This Row],[frecuencia]]="1 semana(s)","Semanal","Horas"))))))))) -> Diaria | F232: =IF(Tabla142[[#This Row],[frecuencia_new]]="Diaria"," ",RANDBETWEEN(1,6)) | G232: =IF(Tabla142[[#This Row],[frecuencia_new]]="Diaria","",IF(Tabla142[[#This Row],[frecuencia_new]]="Semanal","",IF(Tabla142[[#This Row],[frecuencia_new]]="Quincenal",RANDBETWEEN(1,2),RANDBETWEEN(1,4)))) | H232: =IF(Tabla142[[#This Row],[frecuencia_new]]="Trimestral",RANDBETWEEN(1,3),IF(Tabla142[[#This Row],[frecuencia_new]]="Semestral",RANDBETWEEN(1,6),IF(Tabla142[[#This Row],[frecuencia_new]]="Anual",RANDBETWEEN(1,12),""))) | J232: Limpieza de residuos | K232: =SUM(MID(Tabla142[[#This Row],[Duración]],1,2)*60,MID(Tabla142[[#This Row],[Duración]],6,2)) -> 5 | L232: 00 h 05 m | M232: prensas automaticas | N232: CNC 3 | O232: Joel Vasquez | P232: Operador | Q232: 46032.649 | R232: 1 día | T232: 145Joel Vasquez
A233: =VLOOKUP(T233,$V$2:$W$222,2,FALSE) -> 214 | B233: AS232 | C233: Alta | D233: 145 | E233: =IF(Tabla142[[#This Row],[frecuencia]]="1 año","Anual",IF(Tabla142[[#This Row],[frecuencia]]="1 semana","Semanal",IF(Tabla142[[#This Row],[frecuencia]]="Quincenal",Tabla142[[#This Row],[frecuencia]],IF(Tabla142[[#This Row],[frecuencia]]="1 mes","Mensual",IF(Tabla142[[#This Row],[frecuencia]]="3 mes","Trimestral",IF(Tabla142[[#This Row],[frecuencia]]="6 mes","Semestral",IF(Tabla142[[#This Row],[frecuencia]]="1 día","Diaria",IF(Tabla142[[#This Row],[frecuencia]]="1 mes(es)","Mensual",IF(Tabla142[[#This Row],[frecuencia]]="1 semana(s)","Semanal","Horas"))))))))) -> Mensual | F233: =IF(Tabla142[[#This Row],[frecuencia_new]]="Diaria"," ",RANDBETWEEN(1,6)) -> 6 | G233: =IF(Tabla142[[#This Row],[frecuencia_new]]="Diaria","",IF(Tabla142[[#This Row],[frecuencia_new]]="Semanal","",IF(Tabla142[[#This Row],[frecuencia_new]]="Quincenal",RANDBETWEEN(1,2),RANDBETWEEN(1,4)))) -> 2 | H233: =IF(Tabla142[[#This Row],[frecuencia_new]]="Trimestral",RANDBETWEEN(1,3),IF(Tabla142[[#This Row],[frecuencia_new]]="Semestral",RANDBETWEEN(1,6),IF(Tabla142[[#This Row],[frecuencia_new]]="Anual",RANDBETWEEN(1,12),""))) | J233: Comprobación y verificación de fajas | K233: =SUM(MID(Tabla142[[#This Row],[Duración]],1,2)*60,MID(Tabla142[[#This Row],[Duración]],6,2)) -> 10 | L233: 00 h 10 m | M233: prensas automaticas | N233: CNC 3 | O233: Raul Castillo | P233: Mecánico | Q233: 46032.649 | R233: 1 mes | T233: 145Raul Castillo
A234: =VLOOKUP(T234,$V$2:$W$222,2,FALSE) -> 214 | B234: AS233 | C234: Alta | D234: 145 | E234: =IF(Tabla142[[#This Row],[frecuencia]]="1 año","Anual",IF(Tabla142[[#This Row],[frecuencia]]="1 semana","Semanal",IF(Tabla142[[#This Row],[frecuencia]]="Quincenal",Tabla142[[#This Row],[frecuencia]],IF(Tabla142[[#This Row],[frecuencia]]="1 mes","Mensual",IF(Tabla142[[#This Row],[frecuencia]]="3 mes","Trimestral",IF(Tabla142[[#This Row],[frecuencia]]="6 mes","Semestral",IF(Tabla142[[#This Row],[frecuencia]]="1 día","Diaria",IF(Tabla142[[#This Row],[frecuencia]]="1 mes(es)","Mensual",IF(Tabla142[[#This Row],[frecuencia]]="1 semana(s)","Semanal","Horas"))))))))) -> Mensual | F234: =IF(Tabla142[[#This Row],[frecuencia_new]]="Diaria"," ",RANDBETWEEN(1,6)) -> 5 | G234: =IF(Tabla142[[#This Row],[frecuencia_new]]="Diaria","",IF(Tabla142[[#This Row],[frecuencia_new]]="Semanal","",IF(Tabla142[[#This Row],[frecuencia_new]]="Quincenal",RANDBETWEEN(1,2),RANDBETWEEN(1,4)))) -> 4 | H234: =IF(Tabla142[[#This Row],[frecuencia_new]]="Trimestral",RANDBETWEEN(1,3),IF(Tabla142[[#This Row],[frecuencia_new]]="Semestral",RANDBETWEEN(1,6),IF(Tabla142[[#This Row],[frecuencia_new]]="Anual",RANDBETWEEN(1,12),""))) | J234: Comprobación y verificación de fajas de transmisión | K234: =SUM(MID(Tabla142[[#This Row],[Duración]],1,2)*60,MID(Tabla142[[#This Row],[Duración]],6,2)) -> 10 | L234: 00 h 10 m | M234: prensas automaticas | N234: CNC 3 | O234: Raul Castillo | P234: Mecánico | Q234: 46032.649 | R234: 1 mes | T234: 145Raul Castillo
... A306: =VLOOKUP(T306,$V$2:$W$222,2,FALSE) -> 134 | B306: AS305 | C306: Alta | D306: 30 | E306: =IF(Tabla142[[#This Row],[frecuencia]]="1 año","Anual",IF(Tabla142[[#This Row],[frecuencia]]="1 semana","Semanal",IF(Tabla142[[#This Row],[frecuencia]]="Quincenal",Tabla142[[#This Row],[frecuencia]],IF(Tabla142[[#This Row],[frecuencia]]="1 mes","Mensual",IF(Tabla142[[#This Row],[frecuencia]]="3 mes","Trimestral",IF(Tabla142[[#This Row],[frecuencia]]="6 mes","Semestral",IF(Tabla142[[#This Row],[frecuencia]]="1 día","Diaria",IF(Tabla142[[#This Row],[frecuencia]]="1 mes(es)","Mensual",IF(Tabla142[[#This Row],[frecuencia]]="1 semana(s)","Semanal","Horas"))))))))) -> Semanal | F306: =IF(Tabla142[[#This Row],[frecuencia_new]]="Diaria"," ",RANDBETWEEN(1,6)) -> 2 | G306: =IF(Tabla142[[#This Row],[frecuencia_new]]="Diaria","",IF(Tabla142[[#This Row],[frecuencia_new]]="Semanal","",IF(Tabla142[[#This Row],[frecuencia_new]]="Quincenal",RANDBETWEEN(1,2),RANDBETWEEN(1,4)))) | H306: =IF(Tabla142[[#This Row],[frecuencia_new]]="Trimestral",RANDBETWEEN(1,3),IF(Tabla142[[#This Row],[frecuencia_new]]="Semestral",RANDBETWEEN(1,6),IF(Tabla142[[#This Row],[frecuencia_new]]="Anual",RANDBETWEEN(1,12),""))) | J306: Verificar posición de tubo de señales de control e inyección | K306: =SUM(MID(Tabla142[[#This Row],[Duración]],1,2)*60,MID(Tabla142[[#This Row],[Duración]],6,2)) -> 2 | L306: 00 h 02 m | M306: Equipos Auxiliares | N306: Codificadoras | O306: Ever Morales | P306: Electricista | Q306: 46032.649 | R306: 1 semana | T306: 30Ever Morales
